# RAG System Pydantic Compatibility Fix - Resolution Prompt

## üö® URGENT: RAG System Pydantic Compatibility Issue

### **Error Details**
```
RAGTool - ERROR - OpenAI embedding generation failed: Fields must not use names with leading underscores; e.g., use 'pydantic_extra__' instead of '__pydantic_extra__'.
```

### **Context**
- **Environment:** Production (https://insurance-navigator-api.onrender.com)
- **Component:** RAG System / OpenAI Embeddings
- **Impact:** RAG functionality completely broken - no document retrieval possible
- **Priority:** HIGH - Core AI functionality unavailable

### **Investigation Tasks**

#### 1. **Identify the Root Cause**
```bash
# Check current Pydantic version
pip show pydantic

# Check OpenAI client version
pip show openai

# Check for version compatibility issues
pip check
```

#### 2. **Analyze the Error Source**
The error suggests that some dependency is using field names with leading underscores, which is not allowed in Pydantic 2.5.0. This could be:
- OpenAI client library using deprecated Pydantic patterns
- Another dependency using old Pydantic field naming
- Version mismatch between dependencies

#### 3. **Determine Resolution Strategy**

**Option A: Requirements Update (Recommended)**
- Downgrade Pydantic to a compatible version
- Update OpenAI client to latest version
- Ensure all dependencies are compatible

**Option B: Code Update**
- Update RAG system code to handle Pydantic 2.5.0 properly
- Modify OpenAI client usage patterns
- Add compatibility layer

**Option C: Dependency Update**
- Update all AI/ML dependencies to latest versions
- Ensure Pydantic compatibility across the stack

### **Investigation Commands**

#### Check Current Versions
```bash
# Check all AI/ML related package versions
pip list | grep -E "(pydantic|openai|anthropic|langgraph)"

# Check for version conflicts
pip check
```

#### Test RAG System Locally
```bash
# Test RAG system in isolation
python -c "
from agents.tooling.rag.core import RAGTool, RetrievalConfig
import asyncio

async def test_rag():
    config = RetrievalConfig()
    rag = RAGTool('test-user', config)
    try:
        chunks = await rag.retrieve_chunks_from_text('test query')
        print('‚úÖ RAG system working')
    except Exception as e:
        print(f'‚ùå RAG error: {e}')

asyncio.run(test_rag())
"
```

#### Check OpenAI Client Usage
```bash
# Search for OpenAI client usage in RAG system
grep -r "openai\|OpenAI" agents/tooling/rag/
grep -r "AsyncOpenAI" agents/tooling/rag/
```

### **Resolution Steps**

#### Step 1: Identify Compatible Versions
```bash
# Check what versions work together
pip install pydantic==2.4.0 openai==1.12.0
# Test if this resolves the issue

# Or try latest versions
pip install pydantic==2.5.0 openai==1.108.1
# Test if this resolves the issue
```

#### Step 2: Update Requirements
Based on investigation results, update `requirements-api.txt`:
```python
# Option A: Downgrade Pydantic
pydantic==2.4.0

# Option B: Keep Pydantic 2.5.0, update OpenAI
openai==1.108.1

# Option C: Use specific compatible versions
pydantic==2.4.0
openai==1.12.0
```

#### Step 3: Test the Fix
```bash
# Test RAG system functionality
python -c "
import asyncio
from agents.tooling.rag.core import RAGTool, RetrievalConfig

async def test_embedding():
    config = RetrievalConfig()
    rag = RAGTool('test-user', config)
    try:
        # Test embedding generation
        chunks = await rag.retrieve_chunks_from_text('test insurance query')
        print(f'‚úÖ RAG working: {len(chunks)} chunks retrieved')
    except Exception as e:
        print(f'‚ùå RAG failed: {e}')
        import traceback
        traceback.print_exc()

asyncio.run(test_embedding())
"
```

#### Step 4: Test Chat Endpoint
```bash
# Test full chat functionality
curl -X POST "http://localhost:8000/chat" \
  -H "Content-Type: application/json" \
  -H "Authorization: Bearer test-token" \
  -d '{"message": "What is my deductible?", "conversation_id": "test-123"}'
```

### **Expected Root Cause**
Based on the error message, this is likely a **Pydantic 2.5.0 compatibility issue** where:
1. The OpenAI client or a related dependency is using field names with leading underscores
2. Pydantic 2.5.0 has stricter validation rules that reject these field names
3. This breaks the embedding generation process

### **Success Criteria**
- ‚úÖ RAG system generates embeddings without errors
- ‚úÖ Document retrieval works properly
- ‚úÖ Chat endpoint returns relevant responses
- ‚úÖ No Pydantic validation errors in logs

### **Files to Check**
- `requirements-api.txt` - Current dependency versions
- `agents/tooling/rag/core.py` - RAG system implementation
- `agents/tooling/rag/observability.py` - RAG observability
- Any OpenAI client usage in the codebase

### **Quick Commands**
```bash
# Check current working directory
pwd && ls -la

# Check Pydantic version
python -c "import pydantic; print(pydantic.__version__)"

# Check OpenAI version
python -c "import openai; print(openai.__version__)"

# Test RAG system
python -c "from agents.tooling.rag.core import RAGTool; print('RAG import successful')"
```

### **Expected Resolution**
Update dependency versions to ensure Pydantic compatibility. The most likely solution is either:
1. Downgrade Pydantic to 2.4.0 (if OpenAI client is incompatible with 2.5.0)
2. Update OpenAI client to latest version (if it supports Pydantic 2.5.0)
3. Use specific compatible versions of both packages

---

**Created:** 2025-09-22T12:15:00Z  
**Priority:** HIGH - Production outage  
**Estimated Time:** 30-60 minutes  
**Dependencies:** Pydantic, OpenAI client, RAG system
